#include <iostream>
int main() {
    try {
        throw std::runtime_error("An error occurred");
    } catch (const std::exception& e) {
        std::cout << e.what();
    }
    return 0;
}

